[2023-06-10T00:50:43.112+0000] {taskinstance.py:1103} INFO - Dependencies all met for dep_context=non-requeueable deps ti=<TaskInstance: table_check.extract_data manual__2023-06-10T00:45:38.687202+00:00 [queued]>
[2023-06-10T00:50:43.118+0000] {taskinstance.py:1103} INFO - Dependencies all met for dep_context=requeueable deps ti=<TaskInstance: table_check.extract_data manual__2023-06-10T00:45:38.687202+00:00 [queued]>
[2023-06-10T00:50:43.118+0000] {taskinstance.py:1308} INFO - Starting attempt 2 of 2
[2023-06-10T00:50:43.130+0000] {taskinstance.py:1327} INFO - Executing <Task(BashOperator): extract_data> on 2023-06-10 00:45:38.687202+00:00
[2023-06-10T00:50:43.135+0000] {standard_task_runner.py:57} INFO - Started process 45837 to run task
[2023-06-10T00:50:43.141+0000] {standard_task_runner.py:84} INFO - Running: ['airflow', 'tasks', 'run', 'table_check', 'extract_data', 'manual__2023-06-10T00:45:38.687202+00:00', '--job-id', '4', '--raw', '--subdir', 'DAGS_FOLDER/schedule_job_dag.py', '--cfg-path', '/tmp/tmpmtk7y8pb']
[2023-06-10T00:50:43.142+0000] {standard_task_runner.py:85} INFO - Job 4: Subtask extract_data
[2023-06-10T00:50:43.176+0000] {task_command.py:410} INFO - Running <TaskInstance: table_check.extract_data manual__2023-06-10T00:45:38.687202+00:00 [running]> on host database
[2023-06-10T00:50:43.221+0000] {taskinstance.py:1545} INFO - Exporting env vars: AIRFLOW_CTX_DAG_EMAIL='mail@hungtuan.me' AIRFLOW_CTX_DAG_OWNER='Tuan Nguyen' AIRFLOW_CTX_DAG_ID='table_check' AIRFLOW_CTX_TASK_ID='extract_data' AIRFLOW_CTX_EXECUTION_DATE='2023-06-10T00:45:38.687202+00:00' AIRFLOW_CTX_TRY_NUMBER='2' AIRFLOW_CTX_DAG_RUN_ID='manual__2023-06-10T00:45:38.687202+00:00'
[2023-06-10T00:50:43.222+0000] {subprocess.py:63} INFO - Tmp dir root location: 
 /tmp
[2023-06-10T00:50:43.223+0000] {subprocess.py:75} INFO - Running command: ['/usr/bin/bash', '-c', 'python /root/table_check_project/etl_processes/extract_data.py']
[2023-06-10T00:50:43.232+0000] {subprocess.py:86} INFO - Output:
[2023-06-10T00:50:43.245+0000] {subprocess.py:93} INFO -   File "/root/table_check_project/etl_processes/extract_data.py", line 12
[2023-06-10T00:50:43.245+0000] {subprocess.py:93} INFO -     response = wget.download(URL, f'/root/table_check_project/data_files/{FILE_NAME})
[2023-06-10T00:50:43.246+0000] {subprocess.py:93} INFO -                                   ^
[2023-06-10T00:50:43.246+0000] {subprocess.py:93} INFO - SyntaxError: unterminated string literal (detected at line 12)
[2023-06-10T00:50:43.246+0000] {subprocess.py:97} INFO - Command exited with return code 1
[2023-06-10T00:50:43.253+0000] {taskinstance.py:1824} ERROR - Task failed with exception
Traceback (most recent call last):
  File "/root/table_check_project/airflow-env/lib/python3.10/site-packages/airflow/operators/bash.py", line 210, in execute
    raise AirflowException(
airflow.exceptions.AirflowException: Bash command failed. The command returned a non-zero exit code 1.
[2023-06-10T00:50:43.256+0000] {taskinstance.py:1345} INFO - Marking task as FAILED. dag_id=table_check, task_id=extract_data, execution_date=20230610T004538, start_date=20230610T005043, end_date=20230610T005043
[2023-06-10T00:50:43.275+0000] {logging_mixin.py:149} WARNING - /root/table_check_project/airflow-env/lib/python3.10/site-packages/airflow/utils/email.py:152 RemovedInAirflow3Warning: Fetching SMTP credentials from configuration variables will be deprecated in a future release. Please set credentials using a connection instead.
[2023-06-10T00:50:43.276+0000] {configuration.py:676} WARNING - section/key [smtp/smtp_user] not found in config
[2023-06-10T00:50:43.276+0000] {email.py:268} INFO - Email alerting: attempt 1
[2023-06-10T00:50:43.279+0000] {configuration.py:676} WARNING - section/key [smtp/smtp_user] not found in config
[2023-06-10T00:50:43.279+0000] {email.py:268} INFO - Email alerting: attempt 1
[2023-06-10T00:50:43.280+0000] {taskinstance.py:1889} ERROR - Failed to send email to: ['mail@hungtuan.me']
Traceback (most recent call last):
  File "/root/table_check_project/airflow-env/lib/python3.10/site-packages/airflow/models/taskinstance.py", line 1407, in _run_raw_task
    self._execute_task_with_callbacks(context, test_mode)
  File "/root/table_check_project/airflow-env/lib/python3.10/site-packages/airflow/models/taskinstance.py", line 1558, in _execute_task_with_callbacks
    result = self._execute_task(context, task_orig)
  File "/root/table_check_project/airflow-env/lib/python3.10/site-packages/airflow/models/taskinstance.py", line 1628, in _execute_task
    result = execute_callable(context=context)
  File "/root/table_check_project/airflow-env/lib/python3.10/site-packages/airflow/operators/bash.py", line 210, in execute
    raise AirflowException(
airflow.exceptions.AirflowException: Bash command failed. The command returned a non-zero exit code 1.

During handling of the above exception, another exception occurred:

Traceback (most recent call last):
  File "/root/table_check_project/airflow-env/lib/python3.10/site-packages/airflow/models/taskinstance.py", line 2295, in email_alert
    send_email(task.email, subject, html_content)
  File "/root/table_check_project/airflow-env/lib/python3.10/site-packages/airflow/utils/email.py", line 78, in send_email
    return backend(
  File "/root/table_check_project/airflow-env/lib/python3.10/site-packages/airflow/utils/email.py", line 152, in send_email_smtp
    send_mime_email(e_from=mail_from, e_to=recipients, mime_msg=msg, conn_id=conn_id, dryrun=dryrun)
  File "/root/table_check_project/airflow-env/lib/python3.10/site-packages/airflow/utils/email.py", line 270, in send_mime_email
    smtp_conn = _get_smtp_connection(smtp_host, smtp_port, smtp_timeout, smtp_ssl)
  File "/root/table_check_project/airflow-env/lib/python3.10/site-packages/airflow/utils/email.py", line 317, in _get_smtp_connection
    else smtplib.SMTP(host=host, port=port, timeout=timeout)
  File "/usr/lib/python3.10/smtplib.py", line 255, in __init__
    (code, msg) = self.connect(host, port)
  File "/usr/lib/python3.10/smtplib.py", line 341, in connect
    self.sock = self._get_socket(host, port, self.timeout)
  File "/usr/lib/python3.10/smtplib.py", line 312, in _get_socket
    return socket.create_connection((host, port), timeout,
  File "/usr/lib/python3.10/socket.py", line 845, in create_connection
    raise err
  File "/usr/lib/python3.10/socket.py", line 833, in create_connection
    sock.connect(sa)
ConnectionRefusedError: [Errno 111] Connection refused

During handling of the above exception, another exception occurred:

Traceback (most recent call last):
  File "/root/table_check_project/airflow-env/lib/python3.10/site-packages/airflow/models/taskinstance.py", line 1887, in handle_failure
    self.email_alert(error, task)
  File "/root/table_check_project/airflow-env/lib/python3.10/site-packages/airflow/models/taskinstance.py", line 2297, in email_alert
    send_email(task.email, subject, html_content_err)
  File "/root/table_check_project/airflow-env/lib/python3.10/site-packages/airflow/utils/email.py", line 78, in send_email
    return backend(
  File "/root/table_check_project/airflow-env/lib/python3.10/site-packages/airflow/utils/email.py", line 152, in send_email_smtp
    send_mime_email(e_from=mail_from, e_to=recipients, mime_msg=msg, conn_id=conn_id, dryrun=dryrun)
  File "/root/table_check_project/airflow-env/lib/python3.10/site-packages/airflow/utils/email.py", line 270, in send_mime_email
    smtp_conn = _get_smtp_connection(smtp_host, smtp_port, smtp_timeout, smtp_ssl)
  File "/root/table_check_project/airflow-env/lib/python3.10/site-packages/airflow/utils/email.py", line 317, in _get_smtp_connection
    else smtplib.SMTP(host=host, port=port, timeout=timeout)
  File "/usr/lib/python3.10/smtplib.py", line 255, in __init__
    (code, msg) = self.connect(host, port)
  File "/usr/lib/python3.10/smtplib.py", line 341, in connect
    self.sock = self._get_socket(host, port, self.timeout)
  File "/usr/lib/python3.10/smtplib.py", line 312, in _get_socket
    return socket.create_connection((host, port), timeout,
  File "/usr/lib/python3.10/socket.py", line 845, in create_connection
    raise err
  File "/usr/lib/python3.10/socket.py", line 833, in create_connection
    sock.connect(sa)
ConnectionRefusedError: [Errno 111] Connection refused
[2023-06-10T00:50:43.289+0000] {standard_task_runner.py:104} ERROR - Failed to execute job 4 for task extract_data (Bash command failed. The command returned a non-zero exit code 1.; 45837)
[2023-06-10T00:50:43.309+0000] {local_task_job_runner.py:225} INFO - Task exited with return code 1
[2023-06-10T00:50:43.331+0000] {taskinstance.py:2651} INFO - 0 downstream tasks scheduled from follow-on schedule check
